<?xml version="1.0" ?>
<robot name="demo_model" xmlns:xacro="http://www.ros.org/wiki/xacro">

<xacro:include filename="$(find demo_model_description)/urdf/materials.xacro" />
<xacro:include filename="$(find demo_model_description)/urdf/demo_model.trans" />
<xacro:include filename="$(find demo_model_description)/urdf/demo_model.gazebo" />

<link name="base_link">
  <inertial>
    <origin rpy="0 0 0" xyz="-0.001054668620211629 1.7785526445292643e-05 0.032722255550502254"/>
    <mass value="0.2437163627275536"/>
    <inertia ixx="0.000219" ixy="-0.0" ixz="-0.0" iyy="0.000463" iyz="-0.0" izz="0.000642"/>
  </inertial>
  <visual>
    <origin rpy="0 0 0" xyz="0 0 0"/>
    <geometry>
      <mesh filename="package://demo_model_description/meshes/base_link.stl" scale="0.001 0.001 0.001"/>
    </geometry>
    <material name="silver"/>
  </visual>
  <collision>
    <origin rpy="0 0 0" xyz="0 0 0"/>
    <geometry>
      <mesh filename="package://demo_model_description/meshes/base_link.stl" scale="0.001 0.001 0.001"/>
    </geometry>
  </collision>
</link>

<link name="wheel_rf_1">
  <inertial>
    <origin rpy="0 0 0" xyz="-1.3877787807814457e-17 -0.010000000000000002 0.0"/>
    <mass value="0.061720514670588485"/>
    <inertia ixx="1.8e-05" ixy="0.0" ixz="0.0" iyy="3.3e-05" iyz="0.0" izz="1.8e-05"/>
  </inertial>
  <visual>
    <origin rpy="0 0 0" xyz="-0.05 0.055 -0.0325"/>
    <geometry>
      <mesh filename="package://demo_model_description/meshes/wheel_rf_1.stl" scale="0.001 0.001 0.001"/>
    </geometry>
    <material name="silver"/>
  </visual>
  <collision>
    <origin rpy="0 0 0" xyz="-0.05 0.055 -0.0325"/>
    <geometry>
      <mesh filename="package://demo_model_description/meshes/wheel_rf_1.stl" scale="0.001 0.001 0.001"/>
    </geometry>
  </collision>
</link>

<link name="wheel_rb_1">
  <inertial>
    <origin rpy="0 0 0" xyz="0.0 -0.010000000000000002 0.0"/>
    <mass value="0.061720514670588485"/>
    <inertia ixx="1.8e-05" ixy="-0.0" ixz="-0.0" iyy="3.3e-05" iyz="0.0" izz="1.8e-05"/>
  </inertial>
  <visual>
    <origin rpy="0 0 0" xyz="0.05 0.055 -0.0325"/>
    <geometry>
      <mesh filename="package://demo_model_description/meshes/wheel_rb_1.stl" scale="0.001 0.001 0.001"/>
    </geometry>
    <material name="silver"/>
  </visual>
  <collision>
    <origin rpy="0 0 0" xyz="0.05 0.055 -0.0325"/>
    <geometry>
      <mesh filename="package://demo_model_description/meshes/wheel_rb_1.stl" scale="0.001 0.001 0.001"/>
    </geometry>
  </collision>
</link>

<link name="wheel_lb_1">
  <inertial>
    <origin rpy="0 0 0" xyz="0.0 0.010000000000000002 0.0"/>
    <mass value="0.061720514670588485"/>
    <inertia ixx="1.8e-05" ixy="0.0" ixz="-0.0" iyy="3.3e-05" iyz="0.0" izz="1.8e-05"/>
  </inertial>
  <visual>
    <origin rpy="0 0 0" xyz="0.05 -0.055 -0.0325"/>
    <geometry>
      <mesh filename="package://demo_model_description/meshes/wheel_lb_1.stl" scale="0.001 0.001 0.001"/>
    </geometry>
    <material name="silver"/>
  </visual>
  <collision>
    <origin rpy="0 0 0" xyz="0.05 -0.055 -0.0325"/>
    <geometry>
      <mesh filename="package://demo_model_description/meshes/wheel_lb_1.stl" scale="0.001 0.001 0.001"/>
    </geometry>
  </collision>
</link>

<link name="wheel_lf_1">
  <inertial>
    <origin rpy="0 0 0" xyz="-1.3877787807814457e-17 0.010000000000000002 0.0"/>
    <mass value="0.061720514670588485"/>
    <inertia ixx="1.8e-05" ixy="0.0" ixz="0.0" iyy="3.3e-05" iyz="0.0" izz="1.8e-05"/>
  </inertial>
  <visual>
    <origin rpy="0 0 0" xyz="-0.05 -0.055 -0.0325"/>
    <geometry>
      <mesh filename="package://demo_model_description/meshes/wheel_lf_1.stl" scale="0.001 0.001 0.001"/>
    </geometry>
    <material name="silver"/>
  </visual>
  <collision>
    <origin rpy="0 0 0" xyz="-0.05 -0.055 -0.0325"/>
    <geometry>
      <mesh filename="package://demo_model_description/meshes/wheel_lf_1.stl" scale="0.001 0.001 0.001"/>
    </geometry>
  </collision>
</link>

<link name="arm_1">
  <inertial>
    <origin rpy="0 0 0" xyz="0.09997331080702355 -0.015088107062819853 1.3877787807814457e-17"/>
    <mass value="0.03199845679655116"/>
    <inertia ixx="2.4e-05" ixy="2.3e-05" ixz="-0.0" iyy="8e-05" iyz="-0.0" izz="0.000102"/>
  </inertial>
  <visual>
    <origin rpy="0 0 0" xyz="-0.0 -0.0 -0.0725"/>
    <geometry>
      <mesh filename="package://demo_model_description/meshes/arm_1.stl" scale="0.001 0.001 0.001"/>
    </geometry>
    <material name="silver"/>
  </visual>
  <collision>
    <origin rpy="0 0 0" xyz="-0.0 -0.0 -0.0725"/>
    <geometry>
      <mesh filename="package://demo_model_description/meshes/arm_1.stl" scale="0.001 0.001 0.001"/>
    </geometry>
  </collision>
</link>

<link name="gripper_1">
  <inertial>
    <origin rpy="0 0 0" xyz="0.04499999999999997 0.002500000000000009 -0.009999999999999995"/>
    <mass value="0.009540000000000017"/>
    <inertia ixx="0.0" ixy="0.0" ixz="-0.0" iyy="7e-06" iyz="0.0" izz="6e-06"/>
  </inertial>
  <visual>
    <origin rpy="0 0 0" xyz="-0.11 -0.05 -0.0825"/>
    <geometry>
      <mesh filename="package://demo_model_description/meshes/gripper_1.stl" scale="0.001 0.001 0.001"/>
    </geometry>
    <material name="silver"/>
  </visual>
  <collision>
    <origin rpy="0 0 0" xyz="-0.11 -0.05 -0.0825"/>
    <geometry>
      <mesh filename="package://demo_model_description/meshes/gripper_1.stl" scale="0.001 0.001 0.001"/>
    </geometry>
  </collision>
</link>

<joint name="motor_rf" type="continuous">
  <origin rpy="0 0 0" xyz="0.05 -0.055 0.0325"/>
  <parent link="base_link"/>
  <child link="wheel_rf_1"/>
  <axis xyz="0.0 1.0 0.0"/>
</joint>

<joint name="motor_rb" type="continuous">
  <origin rpy="0 0 0" xyz="-0.05 -0.055 0.0325"/>
  <parent link="base_link"/>
  <child link="wheel_rb_1"/>
  <axis xyz="0.0 1.0 0.0"/>
</joint>

<joint name="motor_lb" type="continuous">
  <origin rpy="0 0 0" xyz="-0.05 0.055 0.0325"/>
  <parent link="base_link"/>
  <child link="wheel_lb_1"/>
  <axis xyz="0.0 1.0 0.0"/>
</joint>

<joint name="motor_lf" type="continuous">
  <origin rpy="0 0 0" xyz="0.05 0.055 0.0325"/>
  <parent link="base_link"/>
  <child link="wheel_lf_1"/>
  <axis xyz="0.0 1.0 0.0"/>
</joint>

<joint name="arm_joint" type="revolute">
  <origin rpy="0 0 0" xyz="0.0 0.0 0.0725"/>
  <parent link="base_link"/>
  <child link="arm_1"/>
  <axis xyz="0.0 -1.0 0.0"/>
  <limit effort="100" lower="-0.174533" upper="1.919862" velocity="100"/>
</joint>

<joint name="gripper_joint" type="revolute">
  <origin rpy="0 0 0" xyz="0.11 0.05 0.01"/>
  <parent link="arm_1"/>
  <child link="gripper_1"/>
  <axis xyz="-0.0 0.0 1.0"/>
  <limit effort="100" lower="-1.570796" upper="1.570796" velocity="100"/>
</joint>

</robot>
